<?xml version="1.0"?>
<sdf version="1.10">
  <model name="smart_cleaner_robot">

    <pose>0 0 0.15 0 0 0</pose>

    <!-- BASE -->
    <link name="base_link">

      <inertial>
        <mass>5.0</mass>
        <inertia>
          <ixx>0.1</ixx>
          <iyy>0.1</iyy>
          <izz>0.1</izz>
          <ixy>0</ixy>
          <ixz>0</ixz>
          <iyz>0</iyz>
        </inertia>
      </inertial>

      <collision name="collision">
        <geometry>
          <cylinder>
            <radius>0.25</radius>
            <length>0.2</length>
          </cylinder>
        </geometry>
      </collision>

      <visual name="visual">
        <geometry>
          <cylinder>
            <radius>0.25</radius>
            <length>0.2</length>
          </cylinder>
        </geometry>
        <material>
          <ambient>0.1 0.1 0.8 1</ambient>
          <diffuse>0.2 0.2 1.0 1</diffuse>
        </material>
      </visual>

      <!-- LIDAR -->
      <sensor name="lidar" type="gpu_lidar">
        <pose>0 0 0.2 0 0 0</pose>
        <topic>scan</topic>
        <update_rate>10</update_rate>

        <ray>
          <scan>
            <horizontal>
              <samples>360</samples>
              <min_angle>-3.14</min_angle>
              <max_angle>3.14</max_angle>
            </horizontal>
          </scan>
          <range>
            <min>0.12</min>
            <max>8.0</max>
            <resolution>0.01</resolution>
          </range>
        </ray>

        <always_on>true</always_on>
        <visualize>true</visualize>
      </sensor>

    </link>

    <!-- RUOTA SINISTRA -->
    <link name="left_wheel">
      <pose>0 0.2 0.05 0 1.5708 0</pose>

      <collision name="collision">
        <geometry>
          <cylinder>
            <radius>0.1</radius>
            <length>0.05</length>
          </cylinder>
        </geometry>
      </collision>

      <visual name="visual">
        <geometry>
          <cylinder>
            <radius>0.1</radius>
            <length>0.05</length>
          </cylinder>
        </geometry>
      </visual>
    </link>

    <!-- RUOTA DESTRA -->
    <link name="right_wheel">
      <pose>0 -0.2 0.05 0 1.5708 0</pose>

      <collision name="collision">
        <geometry>
          <cylinder>
            <radius>0.1</radius>
            <length>0.05</length>
          </cylinder>
        </geometry>
      </collision>

      <visual name="visual">
        <geometry>
          <cylinder>
            <radius>0.1</radius>
            <length>0.05</length>
          </cylinder>
        </geometry>
      </visual>
    </link>

    <!-- JOINTS -->
    <joint name="left_wheel_joint" type="revolute">
      <parent>base_link</parent>
      <child>left_wheel</child>
      <axis>
        <xyz>0 1 0</xyz>
      </axis>
    </joint>

    <joint name="right_wheel_joint" type="revolute">
      <parent>base_link</parent>
      <child>right_wheel</child>
      <axis>
        <xyz>0 1 0</xyz>
      </axis>
    </joint>

    <!-- DIFF DRIVE -->
    <plugin filename="gz-sim-diff-drive-system"
            name="gz::sim::systems::DiffDrive">

      <left_joint>left_wheel_joint</left_joint>
      <right_joint>right_wheel_joint</right_joint>

      <wheel_separation>0.4</wheel_separation>
      <wheel_radius>0.1</wheel_radius>

      <topic>cmd_vel</topic>
      <odom_topic>odom</odom_topic>

    </plugin>

  </model>
</sdf>